Workbook

Sheet Thông tin vắn tắt về các thành 
A1: STT | B1: Họ và tên | C1: Năm sinh | D1: Đơn vị học tập/làm việc | E1: Chuyên ngành/ Lĩnh vực làm việc | F1: Vai trò trong dự án | G1: Ghi chú
A2: 1 | B2: Tống Ngọc Khang | C2: 2008 | D2: Đại học Kinh tế Thành phố Hồ Chí Minh - UEH | E2: Kiểm toán | F2: Trưởng nhóm, Quản lý Giải pháp & Chất lượng
A3: 2 | B3: Phạm Quốc Thanh | C3: 2005 | D3: Đại học Quốc tế - Đại học Quốc gia Thành phố Hồ Chí Minh | E3: Tài chính / AI Products | F3: Xây dựng Website, Trí tuệ nhân tạo (AI)
A4: 3 | B4: Nguyễn Ngọc Khánh Phương | C4: 2007 | D4: Trường Đại học Ngoại Thương - Phân hiệu TP.HCM | E4: Product Marketing | F4: Lên kế hoạch kinh doanh, ý tưởng kinh doanh
A5: 4 | B5: Nguyễn Hồng Phúc | C5: 2006 | D5: Trường đại học FPT Hà Nội | E5: Tài Chính | F5: Quản lý Dự án & Lập kế hoạch Tài chính
A6: 5 | B6: Nguyễn Quang Chiến | C6: 2007 | D6: Đại học Bách Khoa - Đại học Đà Nẵng | E6: AI Products | F6: Xây dựng Website, Trí tuệ nhân tạo (AI)

Sheet Tài Chính 2
A1: A. Nguồn thu dự kiến
B2: Nguồn thu | C2: Mô tả | D2: Đối tượng thu | E2: Giai đoạn áp dụng | F2: Ưu tiên | G2: Mức thu đề xuất | H2: Doanh thu tháng = Phí thuê bao + Phí sử dụng theo Monthly Active Driver Giai đoạn pilot (4–6 tuần): không thu phí — đổi lại nhận dữ liệu vận hành thực tế để hiệu chỉnh thuật toán và làm căn cứ định giá. (này consider nên thu hay không nha)
A3: 1 | B3: Phí thuê bao (Subscription) | C3: Thu theo tháng, theo quy mô doanh nghiệp. Bao gồm quyền sử dụng nền tảng, dashboard quản lý, tối ưu tuyến và tính năng vận hành cơ bản. Có hạn mức Active Driver nhất định (Monthly Active Driver) | D3: Doanh nghiệp vận tải, giao hàng, phân phối | E3: Sau pilot (GĐ 2–3) | F3: Cốt lõi của ngành | G3: Gói Starter (≤10 driver): 1.5 - 2.5 triệu/tháng (giảm rào cản gia nhập). Gói nhỏ (≤20 driver): 3–5 triệu/tháng Gói vừa (21–100 driver): 8–15 triệu/tháng Gói lớn (>100 driver): 20–40 triệu/tháng hoặc theo negotiate Vượt hạn mức: +50–100k/driver/tháng
A4: 2 | B4: Phí triển khai & tích hợp | C4: Thu một lần: nhập dữ liệu, đào tạo, tích hợp phần mềm sẵn có | D4: Khách hàng mới | E4: Sau pilot (GĐ 2–3) | F4: Cốt lõi cho ứng dụng | G4: Cơ bản (nhập data + đào tạo): 10–20 triệu Có tích hợp API/ERP: 30–80 triệu tùy độ phức tạp Có thể miễn phí/ giảm 50% cho vài pilot đầu để kéo khách
A5: 3 | B5: Tư vấn & báo cáo ESG | C5: Tư vấn tối ưu chuyên sâu, báo cáo CO₂ chuẩn hóa cho DN xuất khẩu | D5: DN có nhu cầu ESG | E5: Mở rộng (GĐ 4–5) | F5: Bổ sung tùy theo doanh nghiệp cần hay không | G5: Báo cáo CO₂ đơn lẻ: 15–30 triệu/báo cáo (chạy module trên phần mềm) Gói tư vấn theo năm: 100–300 triệu/năm
A6: 4 | B6: Phí kết nối đơn chiều về | C6: Hoa hồng khi ghép đơn chiều về giữa các DN | D6: Mạng lưới logistics tuần hoàn | E6: GĐ 6 (dài hạn) | F6: Có thể phát triển thêm (nếu các đvvc đồng ý từ đầu) | G6: 10–20% giá trị cước tiết kiệm được (ưu tiên hơn do DN thích hơn), hoặc phí cố định 200–500k/đơn ghép thành công
A7: 5 | B7: Hoa hồng đối tác xanh | C7: Giới thiệu khách hàng cho đối tác xe điện/trạm sạc | D7: Đối tác sinh thái | E7: Mở rộng hệ sinh thái (dài hạn) | F7: Tiềm năng cho đvvc có xe điện | G7: 5–15% giá trị hợp đồng đầu (referral fee), hoặc phí cố định 2–10 triệu/lead chuyển đổi
A9: B. Cơ cấu chi phí dự kiến | E9: C. Nhu cầu vốn theo giai đoạn
A10: Nhóm chi phí | B10: Nội dung | C10: Giai đoạn phát sinh | E10: Giai đoạn | F10: Thời gian | G10: Nhu cầu vốn chính | H10: Mục đích sử dụng | I10: Địa bàn / quy mô triển khai
A11: Công nghệ & dữ liệu | B11: Phí API bản đồ/GPS, dữ liệu giao thông; hạ tầng máy chủ, cơ sở dữ liệu, bảo mật | C11: Ngay từ MVP/pilot | E11: GĐ 1 – MVP | F11: 2026 | G11: Vốn nhỏ / nội bộ | H11: Hoàn thiện sản phẩm, kiểm chứng nhu cầu với 3–5 doanh nghiệp | I11: TP.HCM (một số quận nội thành)
A12: Phát triển sản phẩm | B12: Nhân sự lập trình, kiểm thử, hoàn thiện thuật toán VRP | C12: Xuyên suốt các giai đoạn | E12: GĐ 2 – Pilot TP.HCM | F12: 2026-2027 | G12: Vốn hạt giống (seed) | H12: Phí API dữ liệu, vận hành thử nghiệm, hỗ trợ 3–5 DN pilot | I12: TP.HCM (các quận có mật độ giao hàng cao: Quận 1, 3, Bình Thạnh, Phú Nhuận, Quận 7, Thủ Đức)
A13: Vận hành pilot | B13: Hỗ trợ kỹ thuật cho DN thử nghiệm, khảo sát, thu thập dữ liệu | C13: Giai đoạn pilot | E13: GĐ 3 – Tối ưu công nghệ | F13: 2028 | G13: Vốn mở rộng (early-stage) | H13: Tuyển chuyên gia VRP/dữ liệu, nâng cấp hạ tầng, tích hợp GPS & bản đồ số | I13: TP.HCM (toàn thành phố)
A14: Nhân sự chuyên môn bổ sung | B14: Chuyên gia VRP, phân tích dữ liệu, đo lường phát thải (theo mục V.2 đã nêu) | C14: Từ giai đoạn tối ưu công nghệ | E14: GĐ 4–5 – Mở rộng địa bàn & hệ sinh thái | F14: 2028–2030 | G14: Vốn tăng trưởng | H14: Marketing, mở rộng đội ngũ, tích hợp đối tác (kho, phần mềm bán hàng, sàn TMĐT, trạm sạc) | I14: GĐ 4 (2028): Hà Nội (Hoàn Kiếm, Cầu Giấy, Thanh Xuân), Bình Dương (TP. Thủ Dầu Một, Dĩ An), Đà Nẵng (Hải Châu, Cẩm Lệ) GĐ 5 (2029–2030): Đồng Nai (TP. Biên Hòa), mở rộng vùng ven TP.HCM và Hà Nội; thí điểm liên tỉnh ngắn (TP.HCM – Bình Dương – Đồng Nai; Hà Nội – Hưng Yên – Bắc Ninh)
A15: Marketing & tiếp cận khách hàng | B15: Hội thảo, truyền thông, hợp tác hiệp hội/đối tác | C15: Từ giai đoạn pilot trở đi | E15: GĐ 6–7 – Logistics tuần hoàn & liên tỉnh | F15: 2030–2032+ | G15: Vốn quy mô lớn / gọi vốn vòng sau | H15: Xây dựng mạng lưới liên doanh nghiệp, mở rộng vùng địa lý, phát triển logistics liên tỉnh và xuyên biên giới | I15: Vùng kinh tế trọng điểm phía Nam và phía Bắc; các trục logistics liên tỉnh chính; tiến tới kết nối cửa khẩu, cảng biển lớn
A16: Vận hành & duy trì hệ thống | B16: Chi phí server, hỗ trợ khách hàng, cập nhật bảo trì | C16: Khi thương mại hóa

Sheet Business Model Canvas
A1: Business Model Canvas
A2: Đối tác chính (Key Partners) | B2: Hoạt động chính (Key Activities) | C2: Tuyên bố giá trị (Value Propositions) | D2: Quan hệ khách hàng (Customer Relationships) | E2: Phân khúc khách hàng (Customer Segments) | F2: Dòng doanh thu
A3: - Đơn vị cung cấp hạ tầng cloud/server và API bản đồ/GPS. - Các chuyên gia vận tải, logistics và đo lường phát thải. - Hiệp hội logistics và các trường đại học/vườn ươm khởi nghiệp. | B3: - Phát triển và nâng cấp nền tảng SaaS tối ưu tuyến đường (VRP). - Tích hợp dữ liệu giao thông và đo lường phát thải CO_2. - Vận hành chương trình thử nghiệm (Pilot) cho doanh nghiệp. | C3: - Giúp doanh nghiệp tự động phân bổ đơn hàng, tối ưu lộ trình và cắt giảm quãng đường chạy rỗng (VRP). - Kết hợp tối ưu vận hành với đo lường phát thải CO_2. - Giao diện tiếng Việt dễ sử dụng, chi phí phù hợp cho doanh nghiệp vừa và nhỏ | D3: - Hỗ trợ kỹ thuật trực tiếp và trực tuyến trong quá trình sử dụng phần mềm. - Đào tạo, hướng dẫn vận hành đơn giản, dễ tiếp cận cho doanh nghiệp và tài xế. - Tiếp nhận phản hồi từ người dùng để liên tục cải tiến sản phẩm | E3: - Doanh nghiệp logistics vừa và nhỏ, đơn vị giao hàng thương mại điện tử (Shopee, TikTok Shop, Viettel Post, GHN). - Nhà phân phối thực phẩm, đồ uống (F&B), hàng tiêu dùng, nông sản và hàng lạnh. - Siêu thị, nhà hàng, cửa hàng bán lẻ và các đơn vị vận tải nội thành có từ 5–100 phương tiện | F3: - Phí thuê bao (Subscription) thu theo tháng, tính trên số phương tiện quản lý hoặc số tuyến tối ưu. - Phí triển khai và tích hợp thu một lần khi hỗ trợ nhập dữ liệu, đào tạo và kết nối phần mềm. - Dịch vụ tư vấn tối ưu chuyên sâu và lập báo cáo phát thải CO_2 (ESG) chuẩn hóa cho doanh nghiệp.
A4: Nguồn lực chính (Key Resources) | B4: Kênh truyền thông & phân phối (Channels) | C4: Cơ cấu chi phí (Cost Structure)
A5: - Nền tảng công nghệ SaaS (Web & App) tích hợp bản đồ số và thuật toán VRP. - Hệ thống dashboard phân tích, theo dõi thời gian thực và đo lường phát thải CO_2. - Dữ liệu phương tiện, tuyến đường và đội ngũ nhân sự kỹ thuật, chuyên gia logistics | B5: - Tiếp cận trực tiếp qua chương trình dùng thử miễn phí (4–6 tuần). - Hợp tác thông qua hiệp hội logistics, hội doanh nghiệp địa phương và sàn TMĐT. - Truyền thông qua hội thảo chuyên đề ESG và mạng xã hội (LinkedIn, Facebook | C5: 1. Chi phí đầu tư (CAPEX): - Lập trình nền tảng (Web + App), UI/UX và thuật toán tối ưu tuyến (VRP). - Thiết lập hạ tầng server, cơ sở dữ liệu và hệ thống bảo mật. - Chi phí pháp lý, đăng ký doanh nghiệp, hóa đơn điện tử và nhãn hiệu độc quyền. 2. Chi phí vận hành (OPEX): - Biến phí API bản đồ, dữ liệu giao thông thời gian thực và cloud hosting. - Lương nhân sự kỹ thuật, kinh doanh, quản lý và chuyên gia tư vấn. - Chi phí marketing, chương trình dùng thử (pilot) và quỹ dự phòng rủi ro.

Sheet Tài Chính 
A1: Danh mục | B1: Chỉ tiêu chi tiết | C1: Nội dung cụ thể
A2: Nguồn thu | B2: Phí thuê bao (Subscription)
B3: Phí triển khai & tích hợp
B4: Tư vấn & báo cáo ESG | E4: Dự toán chi phí | J4: Chỉ tiêu | K4: Năm 1 (2027) | L4: Năm 2 (2028) | M4: Năm 3 (2029) | N4: Năm 4 (2030) | O4: Năm 5 (2031)
B5: Phí kết nối đơn chiều về | E5: STT | F5: Khoản mục chi phí | G5: Nội dung chi tiết | H5: Dự toán (VND) | J5: Doanh thu dự kiến
E6: CHI PHÍ ĐẦU TƯ BAN ĐẦU | J6: Chi phí vận hành
B7: Hoa hồng đối tác xanh | E7: 1 | F7: Phát triển sản phẩm/công nghệ | G7: Chi phí lập trình xây dựng nền tảng (web + app di động cho tài xế) Chi phí thiết kế UI/UX Chi phí xây dựng thuật toán tối ưu tuyến (VRP) ban đầu Chi phí tích hợp API bản đồ/GPS/giao thông lần đầu (setup fee nếu có) Chi phí xây dựng dashboard phân tích, báo cáo CO₂ Chi phí kiểm thử (QA/testing) trước khi ra mắt | H7: =SUM(CAPEX!G4:G9) -> 97000000 | J7: Khấu hao | K7: ='DEPRECIATION '!E8 -> 15896667 | L7: ='DEPRECIATION '!E8 -> 15896667 | M7: ='DEPRECIATION '!E8 -> 15896667 | N7: ='DEPRECIATION '!E8 -> 15896667 | O7: ='DEPRECIATION '!E8 -> 15896667
A8: Hiệu quả tài chính | E8: 2 | F8: Hạ tầng kỹ thuật | G8: Mua/thiết lập server (nếu không dùng cloud pay-as-you-go) Thiết lập cơ sở dữ liệu ban đầu Thiết lập hệ thống bảo mật, mã hóa dữ liệu | H8: =SUM(CAPEX!G11:G13) -> 10000000 | J8: Lợi nhuận trước thuế | K8: =K5-K6-K7 -> -15896667 | L8: =L5-L6-L7 -> -15896667 | M8: =M5-M6-M7 -> -15896667 | N8: =N5-N6-N7 -> -15896667 | O8: =O5-O6-O7 -> -15896667
E9: 3 | F9: Pháp lý & hành chính | G9: Chi phí mở tài khoản ngân hàng doanh nghiệp Chi phí khởi tạo và cài đặt phần mềm hóa đơn điện tử Phí cung cấp thông tin doanh nghiệp Chi phí mua chữ ký số khai thuế Chi phí khắc con dấu và đăng cáo mẫu dấu Chi phí làm biển hiệu Phí sử dụng hóa đơn điện tử Chi phí soạn thảo hợp đồng với đối tác dữ liệu bản đồ/GPS Phí dịch vụ đăng ký logo độc quyền, bản quyền thương hiệu, nhãn hiệu Lệ phí nộp nhà nước đăng ký độc quyền thương hiệu Tư vấn pháp lý ban đầu | H9: =SUM(CAPEX!G15:G25) -> 21408450
E10: 4 | F10: Thiết bị & tài sản cố định | G10: Laptop Ghế Máy in Bàn Chi phí đặt cọc thuê văn phòng (3 tháng) Thiết bị demo (nếu cần trình diễn cho khách hàng pilot) | H10: =SUM(CAPEX!G27:G32) -> 85190000
E11: 5 | F11: Nghiên cứu & phát triển ban đầu | G11: Chi phí khảo sát thị trường, phỏng vấn doanh nghiệp (trước khi build) Chi phí thuê chuyên gia tư vấn thiết kế hệ thống (one-time) | H11: =SUM(CAPEX!G34:G35) -> 15000000 | J11: Hạng mục (VNĐ) | K11: 2027 (Năm 1) | L11: 2028 (Năm 2) | M11: 2029 (Năm 3) | N11: 2030 (Năm 4) | O11: 2031 (Năm 5)
E12: Tổng | H12: =SUM(H7:H11) -> 228598450
E13: CHI PHÍ VẬN HÀNH | J13: A. DÒNG TIỀN TỪ HĐKD
A14: CAPEX (đầu tư ban đầu - một lần) 1. Phát triển sản phẩm/công nghệ Chi phí lập trình xây dựng nền tảng (web + app di động cho tài xế) Chi phí thiết kế UI/UX Chi phí xây dựng thuật toán tối ưu tuyến (VRP) ban đầu Chi phí tích hợp API bản đồ/GPS/giao thông lần đầu (setup fee nếu có) Chi phí xây dựng dashboard phân tích, báo cáo CO₂ Chi phí kiểm thử (QA/testing) trước khi ra mắt 2. Hạ tầng kỹ thuật Mua/thiết lập server (nếu không dùng cloud pay-as-you-go) Thiết lập cơ sở dữ liệu ban đầu Thiết lập hệ thống bảo mật, mã hóa dữ liệu 3. Pháp lý & hành chính Chi phí mở tài khoản ngân hàng doanh nghiệp Chi phí khởi tạo và cài đặt phần mềm hóa đơn điện tử Phí cung cấp thông tin doanh nghiệp Chi phí mua chữ ký số khai thuế Chi phí khắc con dấu và đăng cáo mẫu dấu Chi phí làm biển hiệu Phí sử dụng hóa đơn điện tử Chi phí soạn thảo hợp đồng với đối tác dữ liệu bản đồ/GPS Phí dịch vụ đăng ký logo độc quyền, bản quyền thương hiệu, nhãn hiệu Lệ phí nộp nhà nước đăng ký độc quyền thương hiệu Tư vấn pháp lý ban đầu 4. Thiết bị & tài sản cố định "Laptop Ghế Máy in Bàn Chi phí đặt cọc thuê văn phòng (3 tháng) Thiết bị demo (nếu cần trình diễn cho khách hàng pilot) " 5. Nghiên cứu & phát triển ban đầu Chi phí khảo sát thị trường, phỏng vấn doanh nghiệp (trước khi build) Chi phí thuê chuyên gia tư vấn thiết kế hệ thống (one-time) OPEX (vận hành - định kỳ theo tháng/quý) 1. Chi phí công nghệ vận hành Phí API bản đồ (Google Maps/Mapbox/HERE...) theo lượt gọi Phí dữ liệu giao thông thời gian thực Phí hosting/cloud server (AWS, GCP, Azure...) Phí lưu trữ dữ liệu (storage) Phí duy trì bảo mật, SSL, backup định kỳ Phí bảo trì, sửa lỗi hệ thống 2. Nhân sự "Lương nhân viên kỹ thuật (dev, duy trì hệ thống) Lương nhân viên kinh doanh/sales Lương nhân viên chăm sóc hành chính - nhân sự Lương quản lý dự án Lương chuyên gia tư vấn dài hạn (logistics, đo lường CO₂, VRP) Lương nhân viên kế toán Bảo hiểm xã hội, phúc lợi nhân viên (nếu tuyển chính thức)" 3. Vận hành pilot/khách hàng Chi phí hỗ trợ kỹ thuật onsite/online cho DN thử nghiệm Chi phí đào tạo, hướng dẫn sử dụng cho DN và tài xế Chi phí thu thập, làm sạch, hiệu chỉnh dữ liệu thực tế Chi phí chương trình dùng thử miễn phí (coi là chi phí "customer acquisition") 4. Marketing & bán hàng Quảng cáo online (Facebook, LinkedIn, Google Ads) Chi phí tham gia hội thảo, triển lãm logistics/ESG Chi phí sản xuất nội dung truyền thông (video, bài viết, case study) Chi phí quà tặng/khuyến mãi cho khách hàng pilot 5. Chi phí văn phòng & hành chính Thuê văn phòng (nếu có), điện, nước, internet Công cụ làm việc: Google Workspace, Slack, Zoom Văn phòng phẩm 6. Chi phí đo lường & báo cáo Công cụ/phần mềm đo lường CO₂ (nếu thuê ngoài thay vì tự xây) Chi phí lập báo cáo ESG định kỳ cho khách hàng 7. Dự phòng rủi ro Quỹ dự phòng phát sinh (thường 10% tổng OPEX) | E14: 6 | F14: Chi phí công nghệ vận hành | G14: Phí API bản đồ (Google Maps/Mapbox/HERE...) theo lượt gọi Phí dữ liệu giao thông thời gian thực Phí hosting/cloud server (AWS, GCP, Azure...) Phí lưu trữ dữ liệu (storage) Phí duy trì bảo mật, SSL, backup định kỳ Phí bảo trì, sửa lỗi hệ thống | H14: =SUM(OPEX!F4:F9) -> 168000000 | J14: 1. Doanh thu dự kiến
E15: 7 | F15: Nhân sự | G15: Lương nhân viên kỹ thuật (dev, duy trì hệ thống) Lương nhân viên kinh doanh/sales Lương nhân viên chăm sóc hành chính - nhân sự Lương quản lý dự án Lương chuyên gia tư vấn dài hạn (logistics, đo lường CO₂, VRP) Lương nhân viên kế toán Bảo hiểm xã hội, phúc lợi nhân viên (nếu tuyển chính thức) | H15: =SUM(OPEX!F11:F16) -> 117115000 | J15: 2. Chi phí vận hành
E16: 8 | F16: Vận hành pilot/khách hàng | G16: Chi phí hỗ trợ kỹ thuật onsite/online cho DN thử nghiệm Chi phí đào tạo, hướng dẫn sử dụng cho DN và tài xế Chi phí thu thập, làm sạch, hiệu chỉnh dữ liệu thực tế Chi phí chương trình dùng thử miễn phí (coi là chi phí "customer acquisition") | H16: =SUM(OPEX!F18:F21) -> 108000000 | J16: 3. Thuế TNDN (20%)
E17: 9 | F17: Marketing & bán hàng | G17: Quảng cáo online (Facebook, LinkedIn, Google Ads) Chi phí tham gia hội thảo, triển lãm logistics/ESG Chi phí sản xuất nội dung truyền thông (video, bài viết, case study) Chi phí quà tặng/khuyến mãi cho khách hàng pilot | H17: =SUM(OPEX!F23:F26) -> 122400000 | J17: Dòng thuần HĐKD (CFO)
E18: 10 | F18: Chi phí văn phòng & hành chính | G18: Thuê văn phòng , điện, nước, internet Công cụ làm việc: Google Workspace, Slack, Zoom Văn phòng phẩm | H18: =SUM(OPEX!F28:F33) -> 199956000 | J18: B. DÒNG TIỀN TỪ HĐĐT
E19: 11 | F19: Chi phí đo lường & báo cáo | G19: Công cụ/phần mềm đo lường CO₂ (nếu thuê ngoài thay vì tự xây) Chi phí lập báo cáo ESG định kỳ cho khách hàng | H19: =SUM(OPEX!F35:F36) -> 42000000 | J19: 1. Vốn đầu tư ban đầu
E20: 12 | F20: Dự phòng rủi ro | G20: Quỹ dự phòng phát sinh (thường 10% tổng OPEX) | H20: =OPEX!F39 -> 188835600 | J20: Dòng thuần HĐĐT (CFI)
E21: Tổng | H21: =SUM(H14:H20) -> 946306600 | J21: C. TỔNG DÒNG TIỀN THUẦN
J23: Chi phí vốn ước tính
J24: Thời gian hoàn vốn
J25: Thời gian hoàn vốn có chiết khấu
J26: NPV - Giá trị hiện tại ròng
J27: IRR - Tỷ suất hoàn vốn nội bộ

Sheet CAPEX
A1: CAPEX
A2: Name of Capitals | D2: Units | E2: Quantity | F2: Price (VND) | G2: Total (VND) | H2: Note
A3: 1. Phát triển sản phẩm/công nghệ
A4: Chi phí lập trình xây dựng nền tảng (web + app di động cho tài xế) | D4: Gói MVP | E4: 1 | F4: 45000000 | G4: =E4*F4 -> 45000000 | H4: Xây dựng Web Điều phối + App di động Flutter cho tài xế (3-4 tháng MVP, 2 dev core)
A5: Chi phí thiết kế UI/UX | D5: Gói thiết kế | E5: 1 | F5: 10000000 | G5: =E5*F5 -> 10000000 | H5: Hệ thống Figma: Web Portal Điều phối, App Tài xế, Dashboard Báo cáo CO2
A6: Chi phí xây dựng thuật toán tối ưu tuyến (VRP) ban đầu | D6: Module Core | E6: 1 | F6: 20000000 | G6: =E6*F6 -> 20000000 | H6: Giải thuật VRPTW đa điểm kết hợp ràng buộc tải trọng xe, khung giờ giao & tình trạng giao thông
A7: Chi phí tích hợp API bản đồ/GPS/giao thông lần đầu (setup fee nếu có) | D7: Lần tích hợp | E7: 1 | F7: 4000000 | G7: =E7*F7 -> 4000000 | H7: Setup fee, SDK integration, Webhook kết nối dữ liệu GPS và API bản đồ Goong/Mapbox
A8: Chi phí xây dựng dashboard phân tích, báo cáo CO₂ | D8: Module Dashboard | E8: 1 | F8: 12000000 | G8: =E8*F8 -> 12000000 | H8: Dashboard phân tích phát thải chuẩn GLEC Framework v3.0 / ISO 14083:2023 / GHG Protocol
A9: Chi phí kiểm thử (QA/testing) trước khi ra mắt | D9: Gói QA/QC | E9: 1 | F9: 6000000 | G9: =E9*F9 -> 6000000 | H9: Manual QA test kịch bản bưu cục + Automated Load Testing 500 CCU tài xế
A10: 2. Hạ tầng kỹ thuật
A11: Mua/thiết lập server (nếu không dùng cloud pay-as-you-go) | D11: Gói setup | E11: 1 | F11: 3500000 | G11: =E11*F11 -> 3500000 | H11: Khởi tạo cụm Docker/K8s, VPC mạng riêng an toàn, CI/CD GitHub Actions deploy
A12: Thiết lập cơ sở dữ liệu ban đầu | D12: Gói CSDL | E12: 1 | F12: 2500000 | G12: =E12*F12 -> 2500000 | H12: PostgreSQL + PostGIS (GIS spatial routing engine) + Redis Caching
A13: Thiết lập hệ thống bảo mật, mã hóa dữ liệu | D13: Gói bảo mật | E13: 1 | F13: 4000000 | G13: =E13*F13 -> 4000000 | H13: Tuân thủ NĐ 13/2023/NĐ-CP bảo vệ dữ liệu cá nhân, SSL EV Wildcard, Cloudflare WAF
A14: 3. Pháp lý & hành chính
A15: Chi phí mở tài khoản ngân hàng doanh nghiệp | D15: Tài khoản | E15: 1 | F15: 0 | G15: =E15*F15 -> 0
A16: Chi phí khởi tạo và cài đặt phần mềm hóa đơn điện tử | D16: Lần | E16: 1 | F16: 2000000 | G16: =E16*F16 -> 2000000
A17: Phí cung cấp thông tin doanh nghiệp | D17: Lần | E17: 1 | F17: 4810000 | G17: =E17*F17 -> 4810000
A18: Chi phí mua chữ ký số khai thuế | D18: Gói | E18: 1 | F18: 3608000 | G18: =E18*F18 -> 3608000 | H18: Chữ ký số VINA-CA ( Gói 3 năm )
A19: Chi phí khắc con dấu và đăng cáo mẫu dấu | D19: Bộ | E19: 1 | F19: 450 | G19: =E19*F19 -> 450
A20: Chi phí làm biển hiệu | D20: Cái | E20: 1 | F20: 1000000 | G20: =E20*F20 -> 1000000
A21: Phí sử dụng hóa đơn điện tử | D21: Hóa đơn | E21: 1000 | F21: 1000 | G21: =E21*F21 -> 1000000
A22: Chi phí soạn thảo hợp đồng với đối tác dữ liệu bản đồ/GPS | D22: Lần | E22: 1 | F22: 5000000 | G22: =E22*F22 -> 5000000 | J22: =SUM(G15:G25) -> 21408450 | K22: https://amis.misa.vn/136043/chi-phi-khi-thanh-lap-doanh-nghiep/ https://luatvietan.vn/chi-phi-thanh-lap-cong-ty.html https://ketoananpha.vn/dich-vu-dang-ky-thuong-hieu.html https://luatsudfc.vn/phi-dich-vu-tu-van-soan-thao-hop-dong.html? https://chukysotot.com/bang-gia-chu-ky-so-cap-nhat-moi-nhat/
A23: Phí dịch vụ đăng ký logo độc quyền, bản quyền thương hiệu, nhãn hiệu | D23: Lần | E23: 1 | F23: 1000000 | G23: =E23*F23 -> 1000000
A24: Lệ phí nộp nhà nước đăng ký độc quyền thương hiệu | D24: Hồ sơ | E24: 1 | F24: 1000000 | G24: =E24*F24 -> 1000000 | H24: Lệ phí nộp đơn đăng ký thương hiệu - 150.000 đồng; Lệ phí công bố đơn đăng ký - 120.000 đồng; Phí tra cứu thông tin nhằm phục vụ việc thẩm định - 180.000 đồng; Phí thẩm định đơn đăng ký - 550.000 đồng.
A25: Tư vấn pháp lý ban đầu | D25: Lần | E25: 1 | F25: 1990000 | G25: =E25*F25 -> 1990000
A26: 4. Thiết bị & tài sản cố định
A27: Laptop | D27: Bộ thiết bị | E27: 2 | F27: 12500000 | G27: =E27*F27 -> 25000000 | H27: 2 Laptop chuyên dụng dev/test phục vụ build môi trường và phân tích dữ liệu
A28: Ghế | D28: Cái | E28: 10 | F28: 300000 | G28: =E28*F28 -> 3000000
A29: Máy in | D29: Cái | E29: 1 | F29: 5690000 | G29: =E29*F29 -> 5690000 | H29: https://www.dienmayxanh.com/may-in/laser-brother-dcpb7620dw
A30: Bàn | D30: Cái | E30: 10 | F30: 700000 | G30: =E30*F30 -> 7000000
A31: Chi phí đặt cọc thuê văn phòng | D31: m² | E31: 50 | F31: 250000 | G31: =E31*F31*3 -> 37500000 | H31: Cọc 3 tháng
A32: Thiết bị demo (nếu cần trình diễn cho khách hàng pilot) | D32: Chiếc | E32: 2 | F32: 3500000 | G32: =E32*F32 -> 7000000 | H32: 2 Smartphone/Tablet cấu hình chuẩn test app tài xế onsite tại bưu cục pilot
A33: 5. Nghiên cứu & phát triển ban đầu
A34: Chi phí khảo sát thị trường, phỏng vấn doanh nghiệp (trước khi build) | D34: Đợt khảo sát | E34: 1 | F34: 5000000 | G34: =E34*F34 -> 5000000 | H34: Chi phí đi lại, khảo sát thực tế và phỏng vấn 15-20 chủ bưu cục/quản lý vận tải TP.HCM
A35: Chi phí thuê chuyên gia tư vấn thiết kế hệ thống (one-time) | D35: Hợp đồng tư vấn | E35: 1 | F35: 10000000 | G35: =E35*F35 -> 10000000 | H35: Tư vấn từ chuyên gia Logistics VLA và chuyên gia giải thuật VRP
A36: Tổng | G36: =SUM(G4:G9)+SUM(G11:G13)+SUM(G15:G25)+SUM(G27:G32)+SUM(G34:G35) -> 228598450

Sheet OPEX
A1: OPEX
A2: Name of Capitals | B2: Units | C2: Quantity | D2: Price (VND) | E2: Total / tháng | F2: Total / năm (VND) | G2: Note | I2: Lương nhân viên
A3: 1 Chi phí công nghệ vận hành | I3: Name of capitals | J3: Quantiy | K3: Cost/month (VND) | L3: Total Cost/month (VND) | M3: Bảo hiểm (VND) | N3: Total
A4: Phí API bản đồ (Google Maps/Mapbox/HERE) theo lượt gọi | B4: Tháng | C4: 1 | D4: 5000000 | E4: =C4*D4 -> 5000000 | F4: =C4*D4*12 -> 60000000 | G4: DAU TB 57-171 (User_acquisition_plan), ~100k-150k routing calls/tháng | Q4: A1 Hệ số quy mô OPEX giai đoạn đầu (so với năm liền sau, do quy mô đội ngũ/khách hàng còn nhỏ)
A5: Phí dữ liệu giao thông thời gian thực | B5: Tháng | C5: 1 | D5: 2500000 | E5: =C5*D5 -> 2500000 | F5: =C5*D5*12 -> 30000000 | G5: API dữ liệu giao thông thời gian thực (Traffic layer & congestion) | I5: Nhân viên kỹ thuật (dev, duy trì hệ thống) | J5: 2 | K5: 13000000 | L5: =K5*J5 -> 26000000 | M5: =K5*21.5% -> 2795000 | N5: =L5+M5 -> 28795000 | O5: Doanh nghiệp có trách nhiệm đóng tổng cộng 215% bảo hiểm Bao gồm tất cả các khoản BHXH, BHYT, BHTN, và kinh phí công đoàn | Q5: Năm | R5: Hệ số so với năm liền sau | S5: Giai đoạn / Diễn giải
A6: Phí hosting/cloud server (AWS, GCP, Azure) | B6: Tháng | C6: 1 | D6: 3500000 | E6: =C6*D6 -> 3500000 | F6: =C6*D6*12 -> 42000000 | G6: 2 Cụm máy chủ ứng dụng (Web Dispatch + Driver API Backend + Load Balancer) | I6: Nhân viên kinh doanh/sales | J6: 2 | K6: 10000000 | L6: =K6*J6 -> 20000000 | M6: =K6*21.5% -> 2150000 | N6: =L6+M6 -> 22150000 | Q6: 2026 | R6: 0.35 | S6: GĐ1 - MVP: đội ngũ lõi nhỏ, xây sản phẩm nội bộ, chưa có KH trả phí, TPHCM (một số quận nội thành)
A7: Phí lưu trữ dữ liệu (storage) | B7: Tháng | C7: 1 | D7: 1200000 | E7: =C7*D7 -> 1200000 | F7: =C7*D7*12 -> 14400000 | G7: Managed PostgreSQL/PostGIS Database + S3 Object Storage lưu trữ lịch sử chuyến | I7: Nhân viên hành chính - nhân sự | J7: 1 | K7: 8000000 | L7: =K7*J7 -> 8000000 | M7: =K7*21.5% -> 1720000 | N7: =L7+M7 -> 9720000 | Q7: 2027 | R7: 0.45 | S7: GĐ2 - Pilot TPHCM (2026-2027): vốn hạt giống, hỗ trợ 3-5 DN pilot, Q1/3/Bình Thạnh/Phú Nhuận/Q7/Thủ Đức
A8: Phí duy trì bảo mật, SSL, backup định kỳ | B8: Tháng | C8: 1 | D8: 800000 | E8: =C8*D8 -> 800000 | F8: =C8*D8*12 -> 9600000 | G8: Chứng chỉ SSL định kỳ, sao lưu CSDL tự động hàng ngày, Cloudflare Security Pro | I8: Quản lý dự án | J8: 3 | K8: 10000000 | L8: =K8*J8 -> 30000000 | M8: =K8*21.5% -> 2150000 | N8: =L8+M8 -> 32150000
A9: Phí bảo trì, sửa lỗi hệ thống | B9: Tháng | C9: 1 | D9: 1000000 | E9: =C9*D9 -> 1000000 | F9: =C9*D9*12 -> 12000000 | G9: Giám sát lỗi tự động (Sentry), APM performance monitoring, bảo trì định kỳ | I9: Chuyên gia tư vấn dài hạn (logistics, đo lường CO₂, VRP) | J9: 1 | K9: 10000000 | L9: =K9*J9 -> 10000000 | M9: =K9*21.5% -> 2150000 | N9: =L9+M9 -> 12150000 | Q9: A2 Giả định tăng trưởng OPEX theo giai đoạn mở rộng (%/năm so với năm liền trước, từ nền 2028)
A10: 2 Nhân sự | I10: Kế toán | J10: 1 | K10: 10000000 | L10: =K10*J10 -> 10000000 | M10: =K10*21.5% -> 2150000 | N10: =L10+M10 -> 12150000 | Q10: Nhóm chi phí | R10: 2029 (GĐ4 - mở rộng HN/Bình Dương/Đà Nẵng) | S10: 2030 (GĐ5 - Đồng Nai, thí điểm liên tỉnh) | T10: 2031 (GĐ6-7 - Logistics tuần hoàn, dài hạn)
A11: Lương nhân viên kỹ thuật (dev, duy trì hệ thống) | B11: Người | C11: 2 | D11: 13000000 | E11: =C11*D11 -> 26000000 | F11: =N5 -> 28795000 | G11: Total đã tính cả BH cho nhân viên | I11: TOTAL | J11: =sum(J5:J10) -> 10 | K11: =SUM(K5:K10) -> 61000000 | L11: =SUM(L5:L10) -> 104000000 | M11: =M5*2+K6*J6+sum(M8:M10) -> 32040000 | N11: =SUM(N5:N10) -> 117115000 | Q11: 1 Chi phí công nghệ vận hành | R11: 0.35 | S11: 0.3 | T11: 0.4
A12: Lương nhân viên kinh doanh/sales | B12: Người | C12: 2 | D12: 10000000 | E12: =C12*D12 -> 20000000 | F12: =N6 -> 22150000 | Q12: 2 Nhân sự | R12: 0.45 | S12: 0.3 | T12: 0.4
A13: Lương nhân viên chăm sóc hành chính - nhân sự | B13: Người | C13: 1 | D13: 8000000 | E13: =C13*D13 -> 8000000 | F13: =N7 -> 9720000 | Q13: 3 Vận hành pilot/khách hàng | R13: 0.25 | S13: 0.25 | T13: 0.35
A14: Lương quản lý dự án | B14: Người | C14: 3 | D14: 10000000 | E14: =C14*D14 -> 30000000 | F14: =N8 -> 32150000 | Q14: 4 Marketing & bán hàng | R14: 0.6 | S14: 0.3 | T14: 0.5
A15: Chuyên gia tư vấn dài hạn (logistics, đo lường CO₂, VRP) | B15: Người | C15: 1 | D15: 10000000 | E15: =C15*D15 -> 10000000 | F15: =N9 -> 12150000 | Q15: 5 Chi phí văn phòng & hành chính | R15: 0.5 | S15: 0.2 | T15: 0.3
A16: Kế toán | B16: Người | C16: 1 | D16: 10000000 | E16: =C16*D16 -> 10000000 | F16: =N10 -> 12150000 | Q16: 6 Chi phí đo lường & báo cáo | R16: 0.4 | S16: 0.3 | T16: 0.4
A17: 3 Vận hành pilot/khách hàng
A18: Chi phí hỗ trợ kỹ thuật onsite/online cho DN thử nghiệm | B18: Tháng | C18: 1 | D18: 2500000 | E18: =C18*D18 -> 2500000 | F18: =C18*D18*12 -> 30000000 | G18: Xăng xe, phụ cấp công tác trực tiếp tại các bưu cục thử nghiệm (2-4 bưu cục) | Q18: B OPEX theo năm 2026-2031 (VND)
A19: Chi phí đào tạo, hướng dẫn sử dụng cho DN và tài xế | B19: Tháng | C19: 1 | D19: 1500000 | E19: =C19*D19 -> 1500000 | F19: =C19*D19*12 -> 18000000 | G19: In ấn tài liệu hướng dẫn nhanh, tổ chức các buổi đào tạo thực địa cho tài xế | Q19: Nhóm chi phí | R19: 2026 (Năm 0) | S19: 2027 (Năm 1) | T19: 2028 (Năm 2) | U19: 2029 (Năm 3) | V19: 2030 (Năm 4) | W19: 2031 (Năm 5)
A20: Chi phí thu thập, làm sạch, hiệu chỉnh dữ liệu thực tế | B20: Tháng | C20: 1 | D20: 2000000 | E20: =C20*D20 -> 2000000 | F20: =C20*D20*12 -> 24000000 | G20: Xử lý chuẩn hóa địa chỉ đơn hàng và hiệu chỉnh thông số tiêu hao nhiên liệu xe | Q20: 1 Chi phí công nghệ vận hành | R20: 26460000 | S20: 75600000 | T20: 168000000 | U20: 226800000 | V20: 294840000 | W20: 412776000
A21: Chi phí chương trình dùng thử miễn phí (coi là chi phí "customer acquisition") | B21: Tháng | C21: 1 | D21: 3000000 | E21: =C21*D21 -> 3000000 | F21: =C21*D21*12 -> 36000000 | G21: Chi phí hỗ trợ/trợ giá dùng thử trong 4-6 tuần đầu để thu thập dữ liệu pilot | Q21: 2 Nhân sự | R21: 18445613 | S21: 52701750 | T21: 117115000 | U21: 169816750 | V21: 220761775 | W21: 309066485
A22: 4 Marketing & bán hàng | Q22: 3 Vận hành pilot/khách hàng | R22: 17010000 | S22: 48600000 | T22: 108000000 | U22: 135000000 | V22: 168750000 | W22: 227812500
A23: Quảng cáo online (Facebook, LinkedIn, Google Ads) | B23: Tháng | C23: 1 | D23: 4000000 | E23: =C23*D23 -> 4000000 | F23: =C23*D23*12 -> 48000000 | G23: Chạy chiến dịch digital marketing nhắm vào nhóm quản lý chuỗi cung ứng/logistics | Q23: 4 Marketing & bán hàng | R23: 19278000 | S23: 55080000 | T23: 122400000 | U23: 195840000 | V23: 254592000 | W23: 381888000
A24: Chi phí tham gia hội thảo, triển lãm logistics/ESG | B24: Tháng | C24: 1 | D24: 2500000 | E24: =C24*D24 -> 2500000 | F24: =C24*D24*12 -> 30000000 | G24: Phân bổ chi phí tham dự các diễn đàn logistics xanh, triển lãm VLA, Green Expo | Q24: 5 Chi phí văn phòng & hành chính | R24: 31493070 | S24: 89980200 | T24: 199956000 | U24: 299934000 | V24: 359920800 | W24: 467897040
A25: Chi phí sản xuất nội dung truyền thông (video, bài viết, case study) | B25: Tháng | C25: 1 | D25: 2500000 | E25: =C25*D25 -> 2500000 | F25: =C25*D25*12 -> 30000000 | G25: Sản xuất video giới thiệu tính năng, bài viết case study chứng minh hiệu quả tiết kiệm | Q25: 6 Chi phí đo lường & báo cáo | R25: 6615000 | S25: 18900000 | T25: 42000000 | U25: 58800000 | V25: 76440000 | W25: 107016000
A26: Chi phí quà tặng/khuyến mãi cho khách hàng pilot | B26: Tháng | C26: 1 | D26: 1200000 | E26: =C26*D26 -> 1200000 | F26: =C26*D26*12 -> 14400000 | G26: Quà lưu niệm, tài trợ vật phẩm cho các bưu cục và tài xế tham gia pilot | Q26: Cộng (trước dự phòng) | R26: 119301683 | S26: 340861950 | T26: 757471000 | U26: 1086190750 | V26: 1375304575 | W26: 1906456025
A27: 5 Chi phí văn phòng & hành chính | Q27: 7 Dự phòng rủi ro | R27: 11930168 | S27: 34086195 | T27: 188835600 | U27: 108619075 | V27: 137530458 | W27: 190645603
A28: Chi phí thuê mặt bằng | B28: m² | C28: 50 | D28: 250000 | E28: =C28*D28 -> 12500000 | F28: =C28*D28*12 -> 150000000 | Q28: TỔNG OPEX NĂM | R28: 131231851 | S28: 374948145 | T28: 946306600 | U28: 1194809825 | V28: 1512835033 | W28: 2097101628
A29: Tiền điện | B29: kWh | C29: 400 | D29: 3500 | E29: =C29*D29 -> 1400000 | F29: =C29*D29*12 -> 16800000
A30: Tiền nước | B30: m³ | C30: 10 | D30: 21300 | E30: =C30*D30 -> 213000 | F30: =C30*D30*12 -> 2556000
A31: Tiền Internet | B31: Tháng | C31: 1 | D31: 450000 | E31: =C31*D31 -> 450000 | F31: =C31*D31*12 -> 5400000
A32: Công cụ làm việc: Google Workspace, Slack, Zoom | B32: Tháng | C32: 1 | D32: 1500000 | E32: =C32*D32 -> 1500000 | F32: =E32*12 -> 18000000 | G32: Bản quyền Google Workspace Business, Slack Pro, Notion, Jira cho 5-8 tài khoản
A33: Văn phòng phẩm | B33: Tháng | C33: 1 | D33: 600000 | E33: =C33*D33 -> 600000 | F33: =E33*12 -> 7200000 | G33: Giấy in, bút, vật dụng văn phòng thiết yếu
A34: 6 Chi phí đo lường & báo cáo
A35: Công cụ/phần mềm đo lường CO₂ (nếu thuê ngoài thay vì tự xây) | B35: Tháng | C35: 1 | D35: 1500000 | E35: =C35*D35 -> 1500000 | F35: =C35*D35*12 -> 18000000 | G35: Cập nhật hệ số phát thải (Emission Factors) chuẩn quốc tế GLEC/IPCC từ cơ sở dữ liệu
A36: Chi phí lập báo cáo ESG định kỳ cho khách hàng | B36: Tháng | C36: 1 | D36: 2000000 | E36: =C36*D36 -> 2000000 | F36: =C36*D36*12 -> 24000000 | G36: Xuất báo cáo định lượng CO₂ tiết giảm và chứng nhận phát thải xanh cho khách hàng B2B
A37: Tổng chi phí vận hành 1 tháng | E37: =SUM(E4:E36) -> 157363000
A38: 7 Dự phòng rủi ro
A39: Quỹ dự phòng phát sinh (thường 10% tổng OPEX) | B39: Tháng | C39: 1 | D39: =E37*10% -> 15736300 | E39: =C39*D39 -> 15736300 | F39: =C39*D39*12 -> 188835600
A40: TỔNG | F40: =SUM(F4:F9)+SUM(F11:F16)+SUM(F18:F21)+SUM(F23:F26)+SUM(F28:F33)+SUM(F35:F36)+F39 -> 946306600

Sheet COGS
A1: COGS = Chi phí công nghệ vận hành biến đổi theo mức sử dụng hệ thống (API bản đồ, dữ liệu giao thông, hosting, storage, bảo mật, bảo trì) Không gồm nhân sự/marketing/văn phòng (các khoản này là OPEX - SG&A)
A3: A Chi tiết khoản mục COGS (nền 2028, link trực tiếp tới sheet OPEX)
A4: STT | B4: Khoản mục | C4: Đơn vị | D4: Số lượng | E4: Đơn giá (VND) | F4: Total/tháng (VND) | G4: Total/năm (VND)
A5: 1 | B5: Phí API bản đồ (Google Maps/Mapbox/HERE) theo lượt gọi | C5: Tháng | D5: 1 | E5: 5000000 | F5: 5000000 | G5: 60000000
A6: 2 | B6: Phí dữ liệu giao thông thời gian thực | C6: Tháng | D6: 1 | E6: 2500000 | F6: 2500000 | G6: 30000000
A7: 3 | B7: Phí hosting/cloud server (AWS, GCP, Azure) | C7: Tháng | D7: 1 | E7: 3500000 | F7: 3500000 | G7: 42000000
A8: 4 | B8: Phí lưu trữ dữ liệu (storage) | C8: Tháng | D8: 1 | E8: 1200000 | F8: 1200000 | G8: 14400000
A9: 5 | B9: Phí duy trì bảo mật, SSL, backup định kỳ | C9: Tháng | D9: 1 | E9: 800000 | F9: 800000 | G9: 9600000
A10: 6 | B10: Phí bảo trì, sửa lỗi hệ thống | C10: Tháng | D10: 1 | E10: 1000000 | F10: 1000000 | G10: 12000000
B11: TỔNG (nền 2028) | F11: 14000000 | G11: 168000000
A13: B Hệ số quy mô & tăng trưởng theo năm (link OPEX - Bảng A1, A2)
A14: Năm | B14: Loại hệ số | C14: Giá trị
A15: 2026 | B15: Hệ số quy mô (so với 2027) | C15: 0.35
A16: 2027 | B16: Hệ số quy mô (so với 2028) | C16: 0.45
A17: 2028 | B17: Nền gốc (100%) | C17: 1
A18: 2029 | B18: Tăng trưởng (so với 2028) | C18: 0.4
A19: 2030 | B19: Tăng trưởng (so với 2029) | C19: 0.35
A20: 2031 | B20: Tăng trưởng (so với 2030) | C20: 0.45
A22: C COGS theo năm 2026-2031 (VND)
A23: Chỉ tiêu | B23: 2026 | C23: 2027 | D23: 2028 | E23: 2029 | F23: 2030 | G23: 2031
A24: COGS | B24: 26460000 | C24: 75600000 | D24: 168000000 | E24: 235200000 | F24: 317520000 | G24: 460404000

Sheet DEPRECIATION 
A1: DEPRECIATION
A2: No | B2: Hạng mục khấu hao | C2: Giá trị đầu tư (VND) | D2: Thời gian (năm) | E2: Khấu hao năm | F2: Khấu hao tháng | G2: Note
A3: 1 | B3: Laptop | C3: 25000000 | D3: 3 | E3: =C3/3 -> 8333333.3 | F3: =E3/12 -> 694444.44 | G3: Thiết bị điện tử văn phòng - khung khấu hao 3-5 năm theo TT45/2013/TT-BTC, chọn 3 năm
A4: 2 | B4: Ghế | C4: 3000000 | D4: 5 | E4: =C4/3 -> 1000000 | F4: =E4/12 -> 83333.333 | G4: Thiết bị/dụng cụ quản lý (nội thất) - khung khấu hao 5-10 năm theo TT45/2013/TT-BTC, chọn 5 năm
A5: 3 | B5: Máy in | C5: 5690000 | D5: 3 | E5: =C5/3 -> 1896666.7 | F5: =E5/12 -> 158055.56 | G5: Thiết bị điện tử văn phòng - khung khấu hao 3-5 năm theo TT45/2013/TT-BTC, chọn 3 năm
A6: 4 | B6: Bàn | C6: 7000000 | D6: 5 | E6: =C6/3 -> 2333333.3 | F6: =E6/12 -> 194444.44 | G6: Thiết bị/dụng cụ quản lý (nội thất) - khung khấu hao 5-10 năm theo TT45/2013/TT-BTC, chọn 5 năm
A7: 5 | B7: Thiết bị demo (smartphone/tablet) | C7: 7000000 | D7: 3 | E7: =C7/3 -> 2333333.3 | F7: =E7/12 -> 194444.44 | G7: Thiết bị điện tử - khung khấu hao 3-5 năm theo TT45/2013/TT-BTC, chọn 3 năm
B8: Tổng | C8: =SUM(C3:C7) -> 47690000 | E8: =SUM(E3:E7) -> 15896667 | F8: =SUM(F3:F7) -> 1324722.2

Sheet Revenue forecasts
A3: Công thức: Doanh thu tháng = Phí thuê bao (Subscription) + Phí sử dụng theo Monthly Active Driver (MAD)
A5: A Giả định đầu vào (driver)
A6: Chỉ tiêu | B6: 2026 | C6: 2027 | D6: 2028 | E6: 2029 | F6: 2030 | G6: 2031
A7: Số DN khách hàng trả phí (cuối năm) | B7: 0 | C7: 4 | D7: 18 | E7: 35 | F7: 60 | G7: 95
A8: Số DN khách hàng trả phí (trung bình trong năm) | B8: 0,0 | C8: 2,0 | D8: 11,0 | E8: 26,5 | F8: 47,5 | G8: 77,5
A9: Số DN mới ký hợp đồng trong năm | B9: 0 | C9: 4 | D9: 14 | E9: 17 | F9: 25 | G9: 35
A10: Monthly Active Driver (MAD) trung bình/DN | B10: 0 | C10: 12 | D10: 15 | E10: 15 | F10: 16 | G10: 16
A11: Giá thuê bao (Subscription)/DN/tháng (VND) | B11: 0 | C11: 6000000 | D11: 6000000 | E11: 6500000 | F11: 6500000 | G11: 7000000
A12: Giá phí sử dụng theo MAD/tài xế/tháng (VND) | B12: 0 | C12: 200000 | D12: 200000 | E12: 220000 | F12: 220000 | G12: 240000
A13: Phí triển khai & tích hợp/DN mới (VND, một lần) | B13: 5000000 | C13: 5000000 | D13: 5000000 | E13: 5000000 | F13: 5000000 | G13: 5000000
A14: Tỷ lệ DN có nhu cầu tư vấn ESG (%) | B14: 0 | C14: 0 | D14: 0 | E14: 0.1 | F14: 0.1 | G14: 0.12
A15: Phí tư vấn & báo cáo ESG/DN có nhu cầu/năm (VND) | B15: 15000000 | C15: 15000000 | D15: 15000000 | E15: 15000000 | F15: 15000000 | G15: 15000000
A16: Tổng phí kết nối đơn chiều về/năm (VND, GĐ6 dài hạn) | B16: 0 | C16: 0 | D16: 0 | E16: 0 | F16: 0 | G16: 20000000
A17: Tổng hoa hồng đối tác xanh/năm (VND, dài hạn) | B17: 0 | C17: 0 | D17: 0 | E17: 0 | F17: 0 | G17: 15000000
A19: B Doanh thu dự kiến theo năm (VND)
A20: Nguồn thu | B20: 2026 | C20: 2027 | D20: 2028 | E20: 2029 | F20: 2030 | G20: 2031
A21: 1 Phí thuê bao (Subscription) | B21: 0 | C21: 144000000 | D21: 792000000 | E21: 2067000000 | F21: 3705000000 | G21: 6510000000
A22: 2 Phí sử dụng theo Monthly Active Driver | B22: 0 | C22: 57600000 | D22: 396000000 | E22: 1049400000 | F22: 2006400000 | G22: 3571200000
A23: 3 Phí triển khai & tích hợp (một lần) | B23: 0 | C23: 20000000 | D23: 70000000 | E23: 85000000 | F23: 125000000 | G23: 175000000
A24: 4 Tư vấn & báo cáo ESG | B24: 0 | C24: 0 | D24: 9900000 | E24: 35775000 | F24: 85500000 | G24: 174375000
A25: 5 Phí kết nối đơn chiều về | B25: 0 | C25: 0 | D25: 0 ₫ | E25: 0 ₫ | F25: 15000000 | G25: 25000000
A26: 6 Hoa hồng đối tác xanh | B26: 0 | C26: 0 | D26: 0 ₫ | E26: 10000000 | F26: 15000000 | G26: 20000000
A27: TỔNG DOANH THU | B27: 0 | C27: 221600000 | D27: 1267900000 | E27: 3247175000 | F27: 5951900000 | G27: 10475575000

Sheet INCOME STATEMENT
A1: Income Statement | I1: Income Statement 2027
A2: No, | B2: Chỉ tiêu | C2: Năm 2027 (VND) | D2: Năm 2028 (VND) | E2: Năm 2029 (VND) | F2: Năm 2030 (VND) | G2: Năm 2031 (VND) | I2: Tháng | J2: Doanh thu (VND) | K2: COGS (VND) | L2: OPEX (VND) | M2: Khấu hao/tháng (VND) | N2: EBIT (VND) | O2: Thuế (20%) | P2: Lợi nhuận ròng (VND)
A3: 1 | B3: Doanh thu thuần (Net Revenue) | C3: 221600000 | D3: 1258000000 | E3: 3241150000 | F3: 5907650000 | G3: 10430700000 | I3: 1 | J3: 18466667 | K3: 6300000 | L3: 24945679 | M3: 794833 | N3: -13573845 | O3: 0 | P3: -13573845
A4: 2 | B4: Giá vốn hàng bán (COGS) | C4: 75600000 | D4: 168000000 | E4: 226800000 | F4: 294840000 | G4: 412776000 | I4: 2 | J4: 18466667 | K4: 6300000 | L4: 24945679 | M4: 794833 | N4: -13573845 | O4: 0 | P4: -13573845
A5: 3 | B5: Lợi nhuận gộp (Gross Profit) | C5: 146000000 | D5: 1090000000 | E5: 3014350000 | F5: 5612810000 | G5: 10017924000 | I5: 3 | J5: 18466667 | K5: 6300000 | L5: 24945679 | M5: 794833 | N5: -13573845 | O5: 0 | P5: -13573845
A6: 4 | B6: Chi phí vận hành (OPEX) | C6: 299348145 | D6: 778306600 | E6: 968009825 | F6: 1217995033 | G6: 1684325628 | I6: 4 | J6: 18466667 | K6: 6300000 | L6: 24945679 | M6: 794833 | N6: -13573845 | O6: 0 | P6: -13573845
A7: 5 | B7: Chi phí khấu hao | C7: 9538000 | D7: 9538000 | E7: 9538000 | F7: 9538000 | G7: 9538000 | I7: 5 | J7: 18466667 | K7: 6300000 | L7: 24945679 | M7: 794833 | N7: -13573845 | O7: 0 | P7: -13573845
A8: 6 | B8: Lợi nhuận hoạt động (Operating Profit / EBIT) | C8: -162886145 | D8: 302155400 | E8: 2036802175 | F8: 4385276968 | G8: 8324060373 | I8: 6 | J8: 18466667 | K8: 6300000 | L8: 24945679 | M8: 794833 | N8: -13573845 | O8: 0 | P8: -13573845
A9: 7 | B9: Thu nhập khác (Other Income) | C9: 0 | D9: 0 | E9: 0 | F9: 0 | G9: 0 | I9: 7 | J9: 18466667 | K9: 6300000 | L9: 24945679 | M9: 794833 | N9: -13573845 | O9: 0 | P9: -13573845
A10: 8 | B10: Chi phí khác (Other Expenses) | C10: 0 | D10: 0 | E10: 0 | F10: 0 | G10: 0 | I10: 8 | J10: 18466667 | K10: 6300000 | L10: 24945679 | M10: 794833 | N10: -13573845 | O10: 0 | P10: -13573845
A11: 9 | B11: Lợi nhuận trước thuế (EBT) | C11: -162886145 | D11: 302155400 | E11: 2036802175 | F11: 4385276968 | G11: 8324060373 | I11: 9 | J11: 18466667 | K11: 6300000 | L11: 24945679 | M11: 794833 | N11: -13573845 | O11: 0 | P11: -13573845
A12: 10 | B12: Thuế thu nhập doanh nghiệp (CIT 20%) | C12: 0 | D12: 60431080 | E12: 407360435 | F12: 877055394 | G12: 1664812075 | I12: 10 | J12: 18466667 | K12: 6300000 | L12: 24945679 | M12: 794833 | N12: -13573845 | O12: 0 | P12: -13573845
A13: 11 | B13: Lợi nhuận ròng (Net Income After Tax) | C13: -162886145 | D13: 241724320 | E13: 1629441740 | F13: 3508221574 | G13: 6659248298 | I13: 11 | J13: 18466667 | K13: 6300000 | L13: 24945679 | M13: 794833 | N13: -13573845 | O13: 0 | P13: -13573845
I14: 12 | J14: 18466667 | K14: 6300000 | L14: 24945679 | M14: 794833 | N14: -13573845 | O14: 0 | P14: -13573845
A15: Tỷ suất lợi nhuận chính | I15: TỔNG NĂM 2027 | J15: 221600000 | K15: 75600000 | L15: 299348145 | M15: 9538000 | N15: -162886145 | O15: 0 | P15: -162886145
A16: No, | B16: Chỉ số | C16: Năm 2026 | D16: Năm 2027 | E16: Năm 2028 | F16: Năm 2029 (VND) | G16: Năm 2030 (VND)
A17: 1 | B17: Gross Profit Margin (Biên lợi nhuận gộp) | C17: =(C3-C4)/C3 -> 0.65884477 | D17: =(D3-D4)/D3 -> 0.86645469 | E17: =(E3-E4)/E3 -> 0.93002484 | F17: =(F3-F4)/F3 -> 0.95009183 | G17: =(G3-G4)/G3 -> 0.96042682
A18: 2 | B18: Operating Profit Margin (Biên lợi nhuận hoạt động) | C18: =C8/C3 -> -0.73504578 | D18: =D8/D3 -> 0.24018712 | E18: =E8/E3 -> 0.6284196 | F18: =F8/F3 -> 0.7423048 | G18: =G8/G3 -> 0.79803468 | I18: Income Statement 2028
A19: 3 | B19: Net Profit Margin (Biên lợi nhuận ròng) | C19: =C13/C3 -> -0.73504578 | D19: =D13/D3 -> 0.1921497 | E19: =E13/E3 -> 0.50273568 | F19: =F13/F3 -> 0.59384384 | G19: =G13/G3 -> 0.63842775 | I19: Tháng | J19: Doanh thu (VND) | K19: COGS (VND) | L19: OPEX (VND) | M19: Khấu hao/tháng (VND) | N19: EBIT (VND) | O19: Thuế (20%) | P19: Lợi nhuận ròng (VND)
A20: 4 | B20: COGS Ratio (Tỷ trọng giá vốn/doanh thu) | C20: =C4/C3 -> 0.34115523 | D20: =D4/D3 -> 0.13354531 | E20: =E4/E3 -> 0.069975163 | F20: =F4/F3 -> 0.04990817 | G20: =G4/G3 -> 0.039573183 | I20: 1 | J20: 105658333 | K20: 14000000 | L20: 64858883 | M20: 794833 | N20: 26004617 | O20: 5200923 | P20: 20803693
A21: 5 | B21: OPEX Ratio (Tỷ trọng chi phí vận hành/doanh thu) | C21: =C6/C3 -> 1.350849 | D21: =D6/D3 -> 0.61868569 | E21: =E6/E3 -> 0.29866246 | F21: =F6/F3 -> 0.20617251 | G21: =G6/G3 -> 0.16147772 | I21: 2 | J21: 105658333 | K21: 14000000 | L21: 64858883 | M21: 794833 | N21: 26004617 | O21: 5200923 | P21: 20803693
I22: 3 | J22: 105658333 | K22: 14000000 | L22: 64858883 | M22: 794833 | N22: 26004617 | O22: 5200923 | P22: 20803693
I23: 4 | J23: 105658333 | K23: 14000000 | L23: 64858883 | M23: 794833 | N23: 26004617 | O23: 5200923 | P23: 20803693
I24: 5 | J24: 105658333 | K24: 14000000 | L24: 64858883 | M24: 794833 | N24: 26004617 | O24: 5200923 | P24: 20803693
I25: 6 | J25: 105658333 | K25: 14000000 | L25: 64858883 | M25: 794833 | N25: 26004617 | O25: 5200923 | P25: 20803693
I26: 7 | J26: 105658333 | K26: 14000000 | L26: 64858883 | M26: 794833 | N26: 26004617 | O26: 5200923 | P26: 20803693
I27: 8 | J27: 105658333 | K27: 14000000 | L27: 64858883 | M27: 794833 | N27: 26004617 | O27: 5200923 | P27: 20803693
I28: 9 | J28: 105658333 | K28: 14000000 | L28: 64858883 | M28: 794833 | N28: 26004617 | O28: 5200923 | P28: 20803693
I29: 10 | J29: 105658333 | K29: 14000000 | L29: 64858883 | M29: 794833 | N29: 26004617 | O29: 5200923 | P29: 20803693
I30: 11 | J30: 105658333 | K30: 14000000 | L30: 64858883 | M30: 794833 | N30: 26004617 | O30: 5200923 | P30: 20803693
I31: 12 | J31: 105658333 | K31: 14000000 | L31: 64858883 | M31: 794833 | N31: 26004617 | O31: 5200923 | P31: 20803693
I32: TỔNG NĂM 2028 | J32: 1267900000 | K32: 168000000 | L32: 778306600 | M32: 9538000 | N32: 312055400 | O32: 62411080 | P32: 249644320
I35: Income Statement 2029
I36: Tháng | J36: Doanh thu (VND) | K36: COGS (VND) | L36: OPEX (VND) | M36: Khấu hao/tháng (VND) | N36: EBIT (VND) | O36: Thuế (20%) | P36: Lợi nhuận ròng (VND)
I37: 1 | J37: 270597917 | K37: 19600000 | L37: 85453470 | M37: 794833 | N37: 164749614 | O37: 32949923 | P37: 131799691
I38: 2 | J38: 270597917 | K38: 19600000 | L38: 85453470 | M38: 794833 | N38: 164749614 | O38: 32949923 | P38: 131799691
I39: 3 | J39: 270597917 | K39: 19600000 | L39: 85453470 | M39: 794833 | N39: 164749614 | O39: 32949923 | P39: 131799691
I40: 4 | J40: 270597917 | K40: 19600000 | L40: 85453470 | M40: 794833 | N40: 164749614 | O40: 32949923 | P40: 131799691
I41: 5 | J41: 270597917 | K41: 19600000 | L41: 85453470 | M41: 794833 | N41: 164749614 | O41: 32949923 | P41: 131799691
I42: 6 | J42: 270597917 | K42: 19600000 | L42: 85453470 | M42: 794833 | N42: 164749614 | O42: 32949923 | P42: 131799691
...

Sheet CASH FLOW
A1: Financial indicators
A2: Year | B2: Cash flow | C2: Cumulative | D2: PV | E2: PV cumiulative
A3: 2026 | B3: =G23+G27 -> -228598450 | C3: =B3 -> -228598450 | D3: =B3 -> -228598450 | E3: =D3 -> -228598450
A4: 2027 | B4: =H23 -> -374948145 | C4: =B4+C3 -> -603546595 | D4: =(B4/1.15^1) -> -3.2604187e+08 | E4: =E3+D4 -> -5.5464032e+08
A5: 2028 | B5: =I23 -> -946306600 | C5: =B5+C4 -> -1549853195 | D5: =(B5/1.15^2) -> -7.1554374e+08 | E5: =E4+D5 -> -1270184058
A6: 2029 | B6: =J23 -> -1194809825 | C6: =B6+C5 -> -2744663020 | D6: =(B6/1.15^3) -> -7.8560685e+08 | E6: =E5+D6 -> -2055790913
A7: 2030 | B7: =K23 -> -1512835033 | C7: =B7+C6 -> -4257498053 | D7: =(B7/1.15^4) -> -8.6496834e+08 | E7: =E6+D7 -> -2920759253
A8: 2031 | B8: =L23 -> -2097101628 | C8: =B8+C7 -> -6354599681 | D8: =(B8/1.15^5) -> -1042630141 | E8: =E7+D8 -> -3963389394
A9: Estimated Cost of capital
A10: Break even point | E10: =I7
A11: Payback Period/ Year | E11: =3+ ABS(C6)/B7 -> 1.1857486
A12: Discounted Paypack period/ Year | E12: =3+ ABS(E6)/D7 -> 0.62327612
A13: NPV | E13: {=NPV(E9,B4:B8)+B3} -> -6354599681
A14: IRR | E14: =IRR(B3:B8) -> #NUM!
F16: CASH FLOW
F17: Hạng mục | G17: Năm 0 (2026) | H17: Năm 1 (2027) | I17: Năm 2 (2028) | J17: Năm 3 (2029) | K17: Năm 4 (2030) | L17: Năm 5 (2031)
F18: A. DÒNG TIỀN TỪ HOẠT ĐỘNG KINH DOANH (Operating Activities)
F19: 1. Tiền nhận được từ sale | G19: 0
F20: 2. Giá vốn bán hàng | G20: 0
F21: 3. Chi phí vận hành OPEX | G21: 0 | H21: =OPEX!S28 -> 374948145 | I21: =OPEX!T28 -> 946306600 | J21: =OPEX!U28 -> 1194809825 | K21: =OPEX!V28 -> 1512835033 | L21: =OPEX!W28 -> 2097101628
F22: 4. Thuế TNDN phải nộp | G22: 0
F23: Dòng tiền thuần từ HĐKD (CFO) | G23: =SUM(G19:G22) -> 0 | H23: =H19-H20-H21-H22 -> -374948145 | I23: =I19-I20-I21-I22 -> -946306600 | J23: =J19-J20-J21-J22 -> -1194809825 | K23: =K19-K20-K21-K22 -> -1512835033 | L23: =L19-L20-L21-L22 -> -2097101628
F24: B. DÒNG TIỀN TỪ HOẠT ĐỘNG ĐẦU TƯ (Investing Activities)
F25: 1. Chi đầu tư tài sản cố định | G25: =-CAPEX!G36 -> -228598450 | H25: 0 | I25: 0 | J25: 0 | K25: 0 | L25: 0
F26: 2. Thanh lý / Thu hồi TSCĐ | G26: 0 | H26: 0 | I26: 0 | J26: 0 | K26: 0 | L26: 0
F27: Dòng tiền thuần từ HĐĐT (CFI) | G27: =G25 -> -228598450
F28: C. DÒNG TIỀN TỪ HOẠT ĐỘNG TÀI CHÍNH (Financing Activities)
F29: 1. Vốn góp / Huy động (Equity funding) | G29: 0 | H29: 0 | I29: 0 | J29: 0 | K29: 0 | L29: 0
F30: 2. Chi trả cổ tức / lãi vay | G30: 0 | H30: 0 | I30: 0 | J30: 0 | K30: 0 | L30: 0
F31: Dòng tiền thuần từ HĐTC (CFF) | G31: =SUM(G29:G30) -> 0 | H31: 0 | I31: 0 | J31: 0 | K31: 0 | L31: 0
F33: D. TỔNG DÒNG TIỀN THUẦN (A + B + C) | G33: =G27+G23+G31 -> -228598450 | H33: =H23+H27+H31 -> -374948145 | I33: =I23+I27+I31 -> -946306600 | J33: =J23+J27+J31 -> -1194809825 | K33: =K23+K27+K31 -> -1512835033 | L33: =L23+L27+L31 -> -2097101628
F34: Tiền tồn đầu kỳ | G34: 0 | H34: =G35 -> -228598450 | I34: =H35 -> -603546595 | J34: =I35 -> -1549853195 | K34: =J35 -> -2744663020 | L34: =K35 -> -4257498053
F35: Tiền tồn cuối kỳ | G35: =G34+G33 -> -228598450 | H35: =H33+H34 -> -603546595 | I35: =I33+I34 -> -1549853195 | J35: =J33+J34 -> -2744663020 | K35: =K33+K34 -> -4257498053 | L35: =L33+L34 -> -6354599681
